Workbook

Sheet cleaned data
A1: SampleID | B1: 1-butanol | C1: 1-heptanol | D1: 1-hexanol | E1: 1-nonanol | F1: 1-octen-3-ol | G1: 2,3 butane diol | H1: 2-heptanol | I1: 2-methyl-1-propanol | J1: 2-methyl-butanoic acid | K1: 2-nonanone | L1: 3,4-dimethylphenol | M1: 3-methyl thiopropanol | N1: 3-methyl-1-butanol | O1: 3-methyl-1-pentanol | P1: 3-octanol | Q1: 4-ethyl guaiacol | R1: 4-ethylphenol | S1: 4-vinylguaiacol | T1: 4-vinylphenol | U1: 5-methylfurfural | V1: acetovanillone | W1: a-ionone | X1: a-terpineol | Y1: b-cintronellol | Z1: b-damascenone | AA1: benzyl alcohol | AB1: b-ionone | AC1: butyl acetate | AD1: butyric acid | AE1: cis-3-hexen-1-ol | AF1: cis-rose-oxide | AG1: cis-whiskey lactone | AH1: decanoic acid | AI1: diacetyl | AJ1: diethyl glutarate | AK1: diethyl succinate | AL1: Ethyl 2-methyl butyrate | AM1: Ethyl 3-methyl butyrate | AN1: Ethyl Acetate | AO1: Ethyl Butyrate | AP1: ethyl cinnamate | AQ1: ethyl decanoate | AR1: ethyl heptanoate | AS1: ethyl hexanoate | AT1: ethyl isobutyrate | AU1: ethyl L-(-)-lactate | AV1: ethyl octanoate | AW1: ethyl vanillate | AX1: ethyl-2-hydroxy-4-methylpentanoate | AY1: eugenol | AZ1: furfural | BA1: furfuryl alcohol | BB1: gamma-nonalactone | BC1: Hexanoic Acid | BD1: hexyl acetate | BE1: isoamyl acetate | BF1: isoamyl lactate | BG1: isobutyl acetate | BH1: isoeugenol | BI1: limonene | BJ1: Linalool | BK1: linalool oxide | BL1: methyl nonanoate | BM1: methyl salicyclate | BN1: methyl vanillate | BO1: nerol | BP1: nerolidol | BQ1: octanoic acid | BR1: phenethyl acetate | BS1: Phenethyl alcohol | BT1: terpinen-4-ol | BU1: trans-2-hexen-1-ol | BV1: trans-2-octen-1-ol | BW1: vanillin
A2: ='raw data'!C3 -> CoBerry-1-1 | B2: ='raw data'!J3 -> 80.330783 | C2: ='raw data'!P3 -> 16.498006 | D2: ='raw data'!V3 -> 0 | E2: ='raw data'!AB3 -> 1.0663582 | F2: ='raw data'!AH3 -> 0.1995125 | G2: ='raw data'!AN3 -> 81158.332 | H2: ='raw data'!AT3 -> 4.8530104 | I2: ='raw data'!AZ3 -> 2750.7619 | J2: ='raw data'!BF3 -> 120.65137 | K2: ='raw data'!BL3 -> 0 | L2: ='raw data'!BR3 -> 0 | M2: ='raw data'!BX3 -> 0 | N2: ='raw data'!CD3 -> 4295.9958 | O2: ='raw data'!CJ3 -> 55.911331 | P2: ='raw data'!CP3 -> 0.57731571 | Q2: ='raw data'!CV3 -> 0.80288396 | R2: ='raw data'!DB3 -> 0 | S2: ='raw data'!DH3 -> 1.1191337 | T2: ='raw data'!DN3 -> 11.852753 | U2: ='raw data'!DT3 -> 1.8807312 | V2: ='raw data'!DZ3 -> 2.847898 | W2: ='raw data'!EF3 -> 0 | X2: ='raw data'!EL3 -> 3.3452245 | Y2: ='raw data'!ER3 -> 13.901689 | Z2: ='raw data'!EX3 -> 1124.1194 | AA2: ='raw data'!FD3 -> 265.28418 | AB2: ='raw data'!FJ3 -> 0.92670216 | AC2: ='raw data'!FP3 -> 0.79494369 | AD2: ='raw data'!FV3 -> 188.61833 | AE2: ='raw data'!GB3 -> 0 | AF2: ='raw data'!GH3 -> 0 | AG2: ='raw data'!GN3 -> 0 | AH2: ='raw data'!HF3 -> 0 | AI2: ='raw data'!HL3 -> 230923.11 | AJ2: ='raw data'!HR3 -> 0 | AK2: ='raw data'!HX3 -> 4.1076672 | AL2: ='raw data'!ID3 -> 1619.491 | AM2: ='raw data'!IJ3 -> 18.307917 | AN2: ='raw data'!IP3 -> 22.42976 | AO2: ='raw data'!IV3 -> 5563.1076 | AP2: ='raw data'!JB3 -> 55.401453 | AQ2: ='raw data'!JH3 -> 0.4231299 | AR2: ='raw data'!JN3 -> 14.037872 | AS2: ='raw data'!JT3 -> 1.4273572 | AT2: ='raw data'!JZ3 -> 10.207492 | AU2: ='raw data'!KF3 -> 400.3772 | AV2: ='raw data'!KL3 -> 21435.572 | AW2: ='raw data'!KR3 -> 145.37834 | AX2: ='raw data'!KX3 -> 0 | AY2: ='raw data'!LD3 -> 5441.1641 | AZ2: ='raw data'!LJ3 -> 0 | BA2: ='raw data'!LP3 -> 11.619044 | BB2: ='raw data'!LV3 -> 262.57484 | BC2: ='raw data'!MB3 -> 6.2670151 | BD2: ='raw data'!MH3 -> 366.16221 | BE2: ='raw data'!MN3 -> 1.3162683 | BF2: ='raw data'!MT3 -> 344.77386 | BG2: ='raw data'!MZ3 -> 560.56389 | BH2: ='raw data'!NF3 -> 0 | BI2: ='raw data'!NL3 -> 0 | BJ2: ='raw data'!NR3 -> 0.19432485 | BK2: ='raw data'!NX3 -> 7.4266935 | BL2: ='raw data'!OD3 -> 8.609931 | BM2: ='raw data'!OJ3 -> 0 | BN2: ='raw data'!OP3 -> 0.62681568 | BO2: ='raw data'!OV3 -> 3.2974894 | BP2: ='raw data'!PB3 -> 0.42058653 | BQ2: ='raw data'!PH3 -> 210.07853 | BR2: ='raw data'!PN3 -> 1145.3635 | BS2: ='raw data'!PT3 -> 24.40157 | BT2: ='raw data'!PZ3 -> 3927.064 | BU2: ='raw data'!QF3 -> 0.22662696 | BV2: ='raw data'!QL3 -> 40.699293 | BW2: ='raw data'!QR3 -> 0
A3: ='raw data'!C4 -> CoBerry-1-2 | B3: ='raw data'!J4 -> 63.666724 | C3: ='raw data'!P4 -> 18.654766 | D3: ='raw data'!V4 -> 171.74243 | E3: ='raw data'!AB4 -> 1.1018587 | F3: ='raw data'!AH4 -> 0.29993873 | G3: ='raw data'!AN4 -> 76245.747 | H3: ='raw data'!AT4 -> 5.2427558 | I3: ='raw data'!AZ4 -> 3217.7623 | J3: ='raw data'!BF4 -> 132.68124 | K3: ='raw data'!BL4 -> 0 | L3: ='raw data'!BR4 -> 0 | M3: ='raw data'!BX4 -> 0 | N3: ='raw data'!CD4 -> 4499.6257 | O3: ='raw data'!CJ4 -> 46.018788 | P3: ='raw data'!CP4 -> 0.61505368 | Q3: ='raw data'!CV4 -> 1.0070577 | R3: ='raw data'!DB4 -> 0 | S3: ='raw data'!DH4 -> 1.1330378 | T3: ='raw data'!DN4 -> 10.655928 | U3: ='raw data'!DT4 -> 2.1224183 | V3: ='raw data'!DZ4 -> 1.5116108 | W3: ='raw data'!EF4 -> 0 | X3: ='raw data'!EL4 -> 4.6953871 | Y3: ='raw data'!ER4 -> 12.720833 | Z3: ='raw data'!EX4 -> 1174.0431 | AA3: ='raw data'!FD4 -> 234.20668 | AB3: ='raw data'!FJ4 -> 1.2206453 | AC3: ='raw data'!FP4 -> 0.81090221 | AD3: ='raw data'!FV4 -> 168.30513 | AE3: ='raw data'!GB4 -> 0 | AF3: ='raw data'!GH4 -> 0 | AG3: ='raw data'!GN4 -> 0 | AH3: ='raw data'!HF4 -> 0 | AI3: ='raw data'!HL4 -> 79524.739 | AJ3: ='raw data'!HR4 -> 676.66581 | AK3: ='raw data'!HX4 -> 4.40243 | AL3: ='raw data'!ID4 -> 2162.4567 | AM3: ='raw data'!IJ4 -> 17.603259 | AN3: ='raw data'!IP4 -> 24.191412 | AO3: ='raw data'!IV4 -> 0 | AP3: ='raw data'!JB4 -> 55.35405 | AQ3: ='raw data'!JH4 -> 0.52357665 | AR3: ='raw data'!JN4 -> 16.199506 | AS3: ='raw data'!JT4 -> 1.6626927 | AT3: ='raw data'!JZ4 -> 11.115049 | AU3: ='raw data'!KF4 -> 347.86333 | AV3: ='raw data'!KL4 -> 12573.292 | AW3: ='raw data'!KR4 -> 166.125 | AX3: ='raw data'!KX4 -> 0 | AY3: ='raw data'!LD4 -> 4556.1747 | AZ3: ='raw data'!LJ4 -> 0 | BA3: ='raw data'!LP4 -> 22.163336 | BB3: ='raw data'!LV4 -> 235.16618 | BC3: ='raw data'!MB4 -> 5.8231163 | BD3: ='raw data'!MH4 -> 484.85344 | BE3: ='raw data'!MN4 -> 1.4793391 | BF3: ='raw data'!MT4 -> 352.27976 | BG3: ='raw data'!MZ4 -> 573.9663 | BH3: ='raw data'!NF4 -> 106.03035 | BI3: ='raw data'!NL4 -> 0 | BJ3: ='raw data'!NR4 -> 0.35912065 | BK3: ='raw data'!NX4 -> 6.1140766 | BL3: ='raw data'!OD4 -> 8.8569735 | BM3: ='raw data'!OJ4 -> 0 | BN3: ='raw data'!OP4 -> 0.52953579 | BO3: ='raw data'!OV4 -> 1.4400919 | BP3: ='raw data'!PB4 -> 0.10668455 | BQ3: ='raw data'!PH4 -> 0 | BR3: ='raw data'!PN4 -> 776.87956 | BS3: ='raw data'!PT4 -> 27.114198 | BT3: ='raw data'!PZ4 -> 2613.3017 | BU3: ='raw data'!QF4 -> 0.24926912 | BV3: ='raw data'!QL4 -> 58.091826 | BW3: ='raw data'!QR4 -> 0
A4: ='raw data'!C5 -> CoBerry-1-3 | B4: ='raw data'!J5 -> 79.451582 | C4: ='raw data'!P5 -> 17.860812 | D4: ='raw data'!V5 -> 185.6413 | E4: ='raw data'!AB5 -> 1.1093663 | F4: ='raw data'!AH5 -> 0.34596711 | G4: ='raw data'!AN5 -> 78923.702 | H4: ='raw data'!AT5 -> 2.4832862 | I4: ='raw data'!AZ5 -> 2847.1497 | J4: ='raw data'!BF5 -> 152.7996 | K4: ='raw data'!BL5 -> 0 | L4: ='raw data'!BR5 -> 0 | M4: ='raw data'!BX5 -> 199.71802 | N4: ='raw data'!CD5 -> 2055.5417 | O4: ='raw data'!CJ5 -> 50.68722 | P4: ='raw data'!CP5 -> 0.52992683 | Q4: ='raw data'!CV5 -> 0.84963247 | R4: ='raw data'!DB5 -> 0 | S4: ='raw data'!DH5 -> 0.84542812 | T4: ='raw data'!DN5 -> 6.2211097 | U4: ='raw data'!DT5 -> 5.7795278 | V4: ='raw data'!DZ5 -> 1.1596179 | W4: ='raw data'!EF5 -> 0 | X4: ='raw data'!EL5 -> 3.9750214 | Y4: ='raw data'!ER5 -> 10.830995 | Z4: ='raw data'!EX5 -> 928.31412 | AA4: ='raw data'!FD5 -> 259.66009 | AB4: ='raw data'!FJ5 -> 0.8322154 | AC4: ='raw data'!FP5 -> 1.1907091 | AD4: ='raw data'!FV5 -> 155.52413 | AE4: ='raw data'!GB5 -> 0 | AF4: ='raw data'!GH5 -> 0 | AG4: ='raw data'!GN5 -> 0 | AH4: ='raw data'!HF5 -> 0 | AI4: ='raw data'!HL5 -> 81039.576 | AJ4: ='raw data'!HR5 -> 9579.0232 | AK4: ='raw data'!HX5 -> 3.8612661 | AL4: ='raw data'!ID5 -> 1822.2011 | AM4: ='raw data'!IJ5 -> 18.984822 | AN4: ='raw data'!IP5 -> 24.558236 | AO4: ='raw data'!IV5 -> 0 | AP4: ='raw data'!JB5 -> 46.461451 | AQ4: ='raw data'!JH5 -> 0.47561059 | AR4: ='raw data'!JN5 -> 15.731134 | AS4: ='raw data'!JT5 -> 1.6524717 | AT4: ='raw data'!JZ5 -> 11.042257 | AU4: ='raw data'!KF5 -> 279.01961 | AV4: ='raw data'!KL5 -> 136388.44 | AW4: ='raw data'!KR5 -> 188.22847 | AX4: ='raw data'!KX5 -> 0 | AY4: ='raw data'!LD5 -> 9011.5403 | AZ4: ='raw data'!LJ5 -> 0 | BA4: ='raw data'!LP5 -> 36.78797 | BB4: ='raw data'!LV5 -> 169.29029 | BC4: ='raw data'!MB5 -> 5.5862953 | BD4: ='raw data'!MH5 -> 471.33117 | BE4: ='raw data'!MN5 -> 1.5075371 | BF4: ='raw data'!MT5 -> 379.30162 | BG4: ='raw data'!MZ5 -> 1352.8584 | BH4: ='raw data'!NF5 -> 107.15252 | BI4: ='raw data'!NL5 -> 0 | BJ4: ='raw data'!NR5 -> 0.37107532 | BK4: ='raw data'!NX5 -> 10.928092 | BL4: ='raw data'!OD5 -> 9.1165211 | BM4: ='raw data'!OJ5 -> 0.000327716 | BN4: ='raw data'!OP5 -> 0.4198091 | BO4: ='raw data'!OV5 -> 0 | BP4: ='raw data'!PB5 -> 0.046563349 | BQ4: ='raw data'!PH5 -> 119.52353 | BR4: ='raw data'!PN5 -> 1054.4503 | BS4: ='raw data'!PT5 -> 27.632868 | BT4: ='raw data'!PZ5 -> 1330.4671 | BU4: ='raw data'!QF5 -> 0.23007748 | BV4: ='raw data'!QL5 -> 38.061855 | BW4: ='raw data'!QR5 -> 0
A5: ='raw data'!C6 -> CoBerry-2-1 | B5: ='raw data'!J6 -> 79.235665 | C5: ='raw data'!P6 -> 18.57341 | D5: ='raw data'!V6 -> 32.20428 | E5: ='raw data'!AB6 -> 1.2802153 | F5: ='raw data'!AH6 -> 0.36724911 | G5: ='raw data'!AN6 -> 66422.906 | H5: ='raw data'!AT6 -> 4.105857 | I5: ='raw data'!AZ6 -> 2157.2075 | J5: ='raw data'!BF6 -> 147.70453 | K5: ='raw data'!BL6 -> 0 | L5: ='raw data'!BR6 -> 0 | M5: ='raw data'!BX6 -> 0 | N5: ='raw data'!CD6 -> 1936.4923 | O5: ='raw data'!CJ6 -> 40.301957 | P5: ='raw data'!CP6 -> 0.5005548 | Q5: ='raw data'!CV6 -> 0.056262553 | R5: ='raw data'!DB6 -> 0 | S5: ='raw data'!DH6 -> 1.5173294 | T5: ='raw data'!DN6 -> 13.57044 | U5: ='raw data'!DT6 -> 1.938738 | V5: ='raw data'!DZ6 -> 0 | W5: ='raw data'!EF6 -> 0 | X5: ='raw data'!EL6 -> 4.0303338 | Y5: ='raw data'!ER6 -> 11.848756 | Z5: ='raw data'!EX6 -> 1257.8988 | AA5: ='raw data'!FD6 -> 214.2833 | AB5: ='raw data'!FJ6 -> 0.41424716 | AC5: ='raw data'!FP6 -> 0.74279672 | AD5: ='raw data'!FV6 -> 113.93373 | AE5: ='raw data'!GB6 -> 0 | AF5: ='raw data'!GH6 -> 0 | AG5: ='raw data'!GN6 -> 0 | AH5: ='raw data'!HF6 -> 0 | AI5: ='raw data'!HL6 -> 131691.5 | AJ5: ='raw data'!HR6 -> 0 | AK5: ='raw data'!HX6 -> 2.9555067 | AL5: ='raw data'!ID6 -> 1035.3178 | AM5: ='raw data'!IJ6 -> 17.397416 | AN5: ='raw data'!IP6 -> 16.671056 | AO5: ='raw data'!IV6 -> 0 | AP5: ='raw data'!JB6 -> 28.177739 | AQ5: ='raw data'!JH6 -> 0.38014635 | AR5: ='raw data'!JN6 -> 12.022011 | AS5: ='raw data'!JT6 -> 1.5526585 | AT5: ='raw data'!JZ6 -> 26.392584 | AU5: ='raw data'!KF6 -> 306.41365 | AV5: ='raw data'!KL6 -> 15110.285 | AW5: ='raw data'!KR6 -> 125.37902 | AX5: ='raw data'!KX6 -> 0 | AY5: ='raw data'!LD6 -> 7063.9695 | AZ5: ='raw data'!LJ6 -> 0 | BA5: ='raw data'!LP6 -> 25.872857 | BB5: ='raw data'!LV6 -> 125.78612 | BC5: ='raw data'!MB6 -> 5.8857461 | BD5: ='raw data'!MH6 -> 450.78152 | BE5: ='raw data'!MN6 -> 1.3760257 | BF5: ='raw data'!MT6 -> 297.58765 | BG5: ='raw data'!MZ6 -> 2574.6022 | BH5: ='raw data'!NF6 -> 75.734326 | BI5: ='raw data'!NL6 -> 0 | BJ5: ='raw data'!NR6 -> 0.31010716 | BK5: ='raw data'!NX6 -> 6.9172669 | BL5: ='raw data'!OD6 -> 10.864703 | BM5: ='raw data'!OJ6 -> 0 | BN5: ='raw data'!OP6 -> 0.41839196 | BO5: ='raw data'!OV6 -> 7.6292132 | BP5: ='raw data'!PB6 -> 0.11076786 | BQ5: ='raw data'!PH6 -> 0 | BR5: ='raw data'!PN6 -> 1493.6738 | BS5: ='raw data'!PT6 -> 22.706765 | BT5: ='raw data'!PZ6 -> 0 | BU5: ='raw data'!QF6 -> 0.18504692 | BV5: ='raw data'!QL6 -> 28.635257 | BW5: ='raw data'!QR6 -> 0
A6: ='raw data'!C7 -> CoBerry-2-2 | B6: ='raw data'!J7 -> 0 | C6: ='raw data'!P7 -> 18.138241 | D6: ='raw data'!V7 -> 58.907869 | E6: ='raw data'!AB7 -> 1.3979125 | F6: ='raw data'!AH7 -> 0.34372839 | G6: ='raw data'!AN7 -> 83898.232 | H6: ='raw data'!AT7 -> 3.1558054 | I6: ='raw data'!AZ7 -> 2358.0593 | J6: ='raw data'!BF7 -> 125.58953 | K6: ='raw data'!BL7 -> 1.5457637 | L6: ='raw data'!BR7 -> 0 | M6: ='raw data'!BX7 -> 0 | N6: ='raw data'!CD7 -> 0 | O6: ='raw data'!CJ7 -> 33.095861 | P6: ='raw data'!CP7 -> 0.94482486 | Q6: ='raw data'!CV7 -> 0.04684816 | R6: ='raw data'!DB7 -> 0 | S6: ='raw data'!DH7 -> 1.6049224 | T6: ='raw data'!DN7 -> 17.103617 | U6: ='raw data'!DT7 -> 1.8541366 | V6: ='raw data'!DZ7 -> 0 | W6: ='raw data'!EF7 -> 0 | X6: ='raw data'!EL7 -> 4.0515853 | Y6: ='raw data'!ER7 -> 12.460814 | Z6: ='raw data'!EX7 -> 1460.7822 | AA6: ='raw data'!FD7 -> 1.5507609 | AB6: ='raw data'!FJ7 -> 2.9341142 | AC6: ='raw data'!FP7 -> 0.84229764 | AD6: ='raw data'!FV7 -> 64.706824 | AE6: ='raw data'!GB7 -> 0 | AF6: ='raw data'!GH7 -> 0 | AG6: ='raw data'!GN7 -> 0 | AH6: ='raw data'!HF7 -> 0 | AI6: ='raw data'!HL7 -> 121675.05 | AJ6: ='raw data'!HR7 -> 8139.1539 | AK6: ='raw data'!HX7 -> 3.5658457 | AL6: ='raw data'!ID7 -> 1102.3553 | AM6: ='raw data'!IJ7 -> 11.651038 | AN6: ='raw data'!IP7 -> 14.069477 | AO6: ='raw data'!IV7 -> 0 | AP6: ='raw data'!JB7 -> 25.508905 | AQ6: ='raw data'!JH7 -> 0.38481927 | AR6: ='raw data'!JN7 -> 12.703595 | AS6: ='raw data'!JT7 -> 1.3318446 | AT6: ='raw data'!JZ7 -> 8.2018709 | AU6: ='raw data'!KF7 -> 311.28469 | AV6: ='raw data'!KL7 -> 0 | AW6: ='raw data'!KR7 -> 131.53727 | AX6: ='raw data'!KX7 -> 0 | AY6: ='raw data'!LD7 -> 4151.1693 | AZ6: ='raw data'!LJ7 -> 0 | BA6: ='raw data'!LP7 -> 22.386958 | BB6: ='raw data'!LV7 -> 504.34625 | BC6: ='raw data'!MB7 -> 8.4772968 | BD6: ='raw data'!MH7 -> 509.42409 | BE6: ='raw data'!MN7 -> 1.1544054 | BF6: ='raw data'!MT7 -> 273.80739 | BG6: ='raw data'!MZ7 -> 505.01903 | BH6: ='raw data'!NF7 -> 97.986815 | BI6: ='raw data'!NL7 -> 0 | BJ6: ='raw data'!NR7 -> 0.32924625 | BK6: ='raw data'!NX7 -> 6.1486072 | BL6: ='raw data'!OD7 -> 9.6197499 | BM6: ='raw data'!OJ7 -> 0.014334646 | BN6: ='raw data'!OP7 -> 0.44447091 | BO6: ='raw data'!OV7 -> 36.221063 | BP6: ='raw data'!PB7 -> 0.15628414 | BQ6: ='raw data'!PH7 -> 1088.2395 | BR6: ='raw data'!PN7 -> 1874.8005 | BS6: ='raw data'!PT7 -> 29.14593 | BT6: ='raw data'!PZ7 -> 0 | BU6: ='raw data'!QF7 -> 0.21275851 | BV6: ='raw data'!QL7 -> 65.492538 | BW6: ='raw data'!QR7 -> 0
A7: ='raw data'!C8 -> CoBerry-2-3 | B7: ='raw data'!J8 -> 107.80836 | C7: ='raw data'!P8 -> 17.802387 | D7: ='raw data'!V8 -> 7.328392 | E7: ='raw data'!AB8 -> 1.4451617 | F7: ='raw data'!AH8 -> 0.44094623 | G7: ='raw data'!AN8 -> 55954.114 | H7: ='raw data'!AT8 -> 2.6537151 | I7: ='raw data'!AZ8 -> 2080.1546 | J7: ='raw data'!BF8 -> 169.50586 | K7: ='raw data'!BL8 -> 0 | L7: ='raw data'!BR8 -> 0 | M7: ='raw data'!BX8 -> 244.39076 | N7: ='raw data'!CD8 -> 1370.971 | O7: ='raw data'!CJ8 -> 36.379171 | P7: ='raw data'!CP8 -> 0.44473175 | Q7: ='raw data'!CV8 -> 0.043884727 | R7: ='raw data'!DB8 -> 0 | S7: ='raw data'!DH8 -> 1.494825 | T7: ='raw data'!DN8 -> 14.066927 | U7: ='raw data'!DT8 -> 1.9764916 | V7: ='raw data'!DZ8 -> 0 | W7: ='raw data'!EF8 -> 0 | X7: ='raw data'!EL8 -> 3.5008598 | Y7: ='raw data'!ER8 -> 13.344514 | Z7: ='raw data'!EX8 -> 1411.8395 | AA7: ='raw data'!FD8 -> 177.1162 | AB7: ='raw data'!FJ8 -> 0.42980182 | AC7: ='raw data'!FP8 -> 0.71662556 | AD7: ='raw data'!FV8 -> 131.87906 | AE7: ='raw data'!GB8 -> 0 | AF7: ='raw data'!GH8 -> 0 | AG7: ='raw data'!GN8 -> 0 | AH7: ='raw data'!HF8 -> 0 | AI7: ='raw data'!HL8 -> 423166.72 | AJ7: ='raw data'!HR8 -> 0 | AK7: ='raw data'!HX8 -> 3.3642195 | AL7: ='raw data'!ID8 -> 892.66593 | AM7: ='raw data'!IJ8 -> 12.349684 | AN7: ='raw data'!IP8 -> 12.995619 | AO7: ='raw data'!IV8 -> 0 | AP7: ='raw data'!JB8 -> 39.050551 | AQ7: ='raw data'!JH8 -> 0.34614846 | AR7: ='raw data'!JN8 -> 12.292487 | AS7: ='raw data'!JT8 -> 1.2734124 | AT7: ='raw data'!JZ8 -> 8.2293373 | AU7: ='raw data'!KF8 -> 302.725 | AV7: ='raw data'!KL8 -> 9869.996 | AW7: ='raw data'!KR8 -> 130.24012 | AX7: ='raw data'!KX8 -> 0 | AY7: ='raw data'!LD8 -> 6499.5645 | AZ7: ='raw data'!LJ8 -> 0 | BA7: ='raw data'!LP8 -> 18.611917 | BB7: ='raw data'!LV8 -> 153.57816 | BC7: ='raw data'!MB8 -> 8.2357699 | BD7: ='raw data'!MH8 -> 360.26561 | BE7: ='raw data'!MN8 -> 1.2966811 | BF7: ='raw data'!MT8 -> 285.88336 | BG7: ='raw data'!MZ8 -> 972.16102 | BH7: ='raw data'!NF8 -> 90.280378 | BI7: ='raw data'!NL8 -> 0 | BJ7: ='raw data'!NR8 -> 0.30621109 | BK7: ='raw data'!NX8 -> 7.1690578 | BL7: ='raw data'!OD8 -> 13.159946 | BM7: ='raw data'!OJ8 -> 0 | BN7: ='raw data'!OP8 -> 0.3511685 | BO7: ='raw data'!OV8 -> 8.0591338 | BP7: ='raw data'!PB8 -> 0.13556403 | BQ7: ='raw data'!PH8 -> 266.4641 | BR7: ='raw data'!PN8 -> 2606.8155 | BS7: ='raw data'!PT8 -> 26.163525 | BT7: ='raw data'!PZ8 -> 0 | BU7: ='raw data'!QF8 -> 0.13258704 | BV7: ='raw data'!QL8 -> 29.018259 | BW7: ='raw data'!QR8 -> 0.000463464
A8: ='raw data'!C9 -> CoBerry-3-1 | B8: ='raw data'!J9 -> 0 | C8: ='raw data'!P9 -> 19.411148 | D8: ='raw data'!V9 -> 200.35327 | E8: ='raw data'!AB9 -> 1.436969 | F8: ='raw data'!AH9 -> 0.4359036 | G8: ='raw data'!AN9 -> 81903.927 | H8: ='raw data'!AT9 -> 3.4588515 | I8: ='raw data'!AZ9 -> 3487.5364 | J8: ='raw data'!BF9 -> 166.0679 | K8: ='raw data'!BL9 -> 0 | L8: ='raw data'!BR9 -> 0 | M8: ='raw data'!BX9 -> 150.21366 | N8: ='raw data'!CD9 -> 2859.0893 | O8: ='raw data'!CJ9 -> 58.999385 | P8: ='raw data'!CP9 -> 0.46341172 | Q8: ='raw data'!CV9 -> 0.14069065 | R8: ='raw data'!DB9 -> 0 | S8: ='raw data'!DH9 -> 1.3102709 | T8: ='raw data'!DN9 -> 10.41235 | U8: ='raw data'!DT9 -> 2.2146582 | V8: ='raw data'!DZ9 -> 0 | W8: ='raw data'!EF9 -> 0 | X8: ='raw data'!EL9 -> 4.3196828 | Y8: ='raw data'!ER9 -> 12.82593 | Z8: ='raw data'!EX9 -> 1504.6997 | AA8: ='raw data'!FD9 -> 329.787 | AB8: ='raw data'!FJ9 -> 0.88344418 | AC8: ='raw data'!FP9 -> 1.4635749 | AD8: ='raw data'!FV9 -> 160.52389 | AE8: ='raw data'!GB9 -> 0 | AF8: ='raw data'!GH9 -> 0 | AG8: ='raw data'!GN9 -> 0 | AH8: ='raw data'!HF9 -> 0 | AI8: ='raw data'!HL9 -> 410967.8 | AJ8: ='raw data'!HR9 -> 1718.7284 | AK8: ='raw data'!HX9 -> 5.1956945 | AL8: ='raw data'!ID9 -> 2110.5437 | AM8: ='raw data'!IJ9 -> 20.618081 | AN8: ='raw data'!IP9 -> 23.529019 | AO8: ='raw data'!IV9 -> 0 | AP8: ='raw data'!JB9 -> 37.567758 | AQ8: ='raw data'!JH9 -> 0.50900488 | AR8: ='raw data'!JN9 -> 15.174127 | AS8: ='raw data'!JT9 -> 1.9515265 | AT8: ='raw data'!JZ9 -> 11.426605 | AU8: ='raw data'!KF9 -> 304.71348 | AV8: ='raw data'!KL9 -> 90949.148 | AW8: ='raw data'!KR9 -> 170.18238 | AX8: ='raw data'!KX9 -> 0 | AY8: ='raw data'!LD9 -> 6496.3343 | AZ8: ='raw data'!LJ9 -> 0 | BA8: ='raw data'!LP9 -> 31.671036 | BB8: ='raw data'!LV9 -> 173.79321 | BC8: ='raw data'!MB9 -> 6.9428658 | BD8: ='raw data'!MH9 -> 520.41457 | BE8: ='raw data'!MN9 -> 1.4223059 | BF8: ='raw data'!MT9 -> 290.95993 | BG8: ='raw data'!MZ9 -> 973.84794 | BH8: ='raw data'!NF9 -> 112.70261 | BI8: ='raw data'!NL9 -> 0 | BJ8: ='raw data'!NR9 -> 0.35242626 | BK8: ='raw data'!NX9 -> 14.787841 | BL8: ='raw data'!OD9 -> 9.1429517 | BM8: ='raw data'!OJ9 -> 0 | BN8: ='raw data'!OP9 -> 0.43759448 | BO8: ='raw data'!OV9 -> 2.4115905 | BP8: ='raw data'!PB9 -> 0.12075557 | BQ8: ='raw data'!PH9 -> 598.37312 | BR8: ='raw data'!PN9 -> 1576.5282 | BS8: ='raw data'!PT9 -> 27.729932 | BT8: ='raw data'!PZ9 -> 0 | BU8: ='raw data'!QF9 -> 0.26061567 | BV8: ='raw data'!QL9 -> 45.076609 | BW8: ='raw data'!QR9 -> 0
A9: ='raw data'!C10 -> CoBerry-3-2 | B9: ='raw data'!J10 -> 0 | C9: ='raw data'!P10 -> 19.585844 | D9: ='raw data'!V10 -> 198.57263 | E9: ='raw data'!AB10 -> 1.4125223 | F9: ='raw data'!AH10 -> 0.4784249 | G9: ='raw data'!AN10 -> 129504.72 | H9: ='raw data'!AT10 -> 4.9019971 | I9: ='raw data'!AZ10 -> 4034.1993 | J9: ='raw data'!BF10 -> 158.34484 | K9: ='raw data'!BL10 -> 0 | L9: ='raw data'!BR10 -> 0 | M9: ='raw data'!BX10 -> 33.048927 | N9: ='raw data'!CD10 -> 0 | O9: ='raw data'!CJ10 -> 47.674046 | P9: ='raw data'!CP10 -> 0.60141999 | Q9: ='raw data'!CV10 -> 0.14264767 | R9: ='raw data'!DB10 -> 0 | S9: ='raw data'!DH10 -> 1.4008869 | T9: ='raw data'!DN10 -> 15.64945 | U9: ='raw data'!DT10 -> 2.4250138 | V9: ='raw data'!DZ10 -> 3.1296789 | W9: ='raw data'!EF10 -> 0 | X9: ='raw data'!EL10 -> 4.0586649 | Y9: ='raw data'!ER10 -> 12.371537 | Z9: ='raw data'!EX10 -> 1638.2194 | AA9: ='raw data'!FD10 -> 263.84875 | AB9: ='raw data'!FJ10 -> 2.1951647 | AC9: ='raw data'!FP10 -> 1.3777014 | AD9: ='raw data'!FV10 -> 78.940315 | AE9: ='raw data'!GB10 -> 0 | AF9: ='raw data'!GH10 -> 0 | AG9: ='raw data'!GN10 -> 0 | AH9: ='raw data'!HF10 -> 0 | AI9: ='raw data'!HL10 -> 542051.76 | AJ9: ='raw data'!HR10 -> 7638.6148 | AK9: ='raw data'!HX10 -> 6.1567142 | AL9: ='raw data'!ID10 -> 2304.6375 | AM9: ='raw data'!IJ10 -> 19.270066 | AN9: ='raw data'!IP10 -> 22.498089 | AO9: ='raw data'!IV10 -> 0 | AP9: ='raw data'!JB10 -> 38.72912 | AQ9: ='raw data'!JH10 -> 0.53783526 | AR9: ='raw data'!JN10 -> 15.680307 | AS9: ='raw data'!JT10 -> 2.0075297 | AT9: ='raw data'!JZ10 -> 10.099873 | AU9: ='raw data'!KF10 -> 279.67417 | AV9: ='raw data'!KL10 -> 52498.127 | AW9: ='raw data'!KR10 -> 165.94604 | AX9: ='raw data'!KX10 -> 0 | AY9: ='raw data'!LD10 -> 5178.6434 | AZ9: ='raw data'!LJ10 -> 0 | BA9: ='raw data'!LP10 -> 33.330797 | BB9: ='raw data'!LV10 -> 394.95524 | BC9: ='raw data'!MB10 -> 8.4751167 | BD9: ='raw data'!MH10 -> 485.25532 | BE9: ='raw data'!MN10 -> 1.520249 | BF9: ='raw data'!MT10 -> 310.13005 | BG9: ='raw data'!MZ10 -> 689.64516 | BH9: ='raw data'!NF10 -> 179.92498 | BI9: ='raw data'!NL10 -> 0 | BJ9: ='raw data'!NR10 -> 0.45834888 | BK9: ='raw data'!NX10 -> 4.0909342 | BL9: ='raw data'!OD10 -> 8.7936127 | BM9: ='raw data'!OJ10 -> 0 | BN9: ='raw data'!OP10 -> 0.44674711 | BO9: ='raw data'!OV10 -> 7.5323509 | BP9: ='raw data'!PB10 -> 0.026781492 | BQ9: ='raw data'!PH10 -> 347.68643 | BR9: ='raw data'!PN10 -> 1602.6406 | BS9: ='raw data'!PT10 -> 31.852932 | BT9: ='raw data'!PZ10 -> 28.926517 | BU9: ='raw data'!QF10 -> 0.33045698 | BV9: ='raw data'!QL10 -> 72.030703 | BW9: ='raw data'!QR10 -> 0
A10: ='raw data'!C11 -> CoCiNe-1-1 | B10: ='raw data'!J11 -> 213.62386 | C10: ='raw data'!P11 -> 18.264747 | D10: ='raw data'!V11 -> 208.01939 | E10: ='raw data'!AB11 -> 1.0836889 | F10: ='raw data'!AH11 -> 0.52234385 | G10: ='raw data'!AN11 -> 129205.64 | H10: ='raw data'!AT11 -> 3.5784908 | I10: ='raw data'!AZ11 -> 2922.0742 | J10: ='raw data'!BF11 -> 216.35554 | K10: ='raw data'!BL11 -> 2.4744745 | L10: ='raw data'!BR11 -> 0 | M10: ='raw data'!BX11 -> 0 | N10: ='raw data'!CD11 -> 0 | O10: ='raw data'!CJ11 -> 48.855102 | P10: ='raw data'!CP11 -> 0.5338072 | Q10: ='raw data'!CV11 -> 0.20445952 | R10: ='raw data'!DB11 -> 0 | S10: ='raw data'!DH11 -> 1.1743794 | T10: ='raw data'!DN11 -> 18.845318 | U10: ='raw data'!DT11 -> 5.2498432 | V10: ='raw data'!DZ11 -> 1.9911254 | W10: ='raw data'!EF11 -> 0.016385036 | X10: ='raw data'!EL11 -> 4.2292085 | Y10: ='raw data'!ER11 -> 15.746077 | Z10: ='raw data'!EX11 -> 1380.6842 | AA10: ='raw data'!FD11 -> 19.309007 | AB10: ='raw data'!FJ11 -> 2.9551998 | AC10: ='raw data'!FP11 -> 2.03624 | AD10: ='raw data'!FV11 -> 81.532461 | AE10: ='raw data'!GB11 -> 0 | AF10: ='raw data'!GH11 -> 0 | AG10: ='raw data'!GN11 -> 0 | AH10: ='raw data'!HF11 -> 0 | AI10: ='raw data'!HL11 -> 181915.87 | AJ10: ='raw data'!HR11 -> 2264.6617 | AK10: ='raw data'!HX11 -> 5.1385601 | AL10: ='raw data'!ID11 -> 1921.5122 | AM10: ='raw data'!IJ11 -> 24.19715 | AN10: ='raw data'!IP11 -> 29.001291 | AO10: ='raw data'!IV11 -> 3067.5401 | AP10: ='raw data'!JB11 -> 36.354366 | AQ10: ='raw data'!JH11 -> 0.52037518 | AR10: ='raw data'!JN11 -> 15.840403 | AS10: ='raw data'!JT11 -> 2.0607429 | AT10: ='raw data'!JZ11 -> 10.061795 | AU10: ='raw data'!KF11 -> 301.76437 | AV10: ='raw data'!KL11 -> 0 | AW10: ='raw data'!KR11 -> 173.30766 | AX10: ='raw data'!KX11 -> 0 | AY10: ='raw data'!LD11 -> 5593.7142 | AZ10: ='raw data'!LJ11 -> 0 | BA10: ='raw data'!LP11 -> 73.381494 | BB10: ='raw data'!LV11 -> 531.24901 | BC10: ='raw data'!MB11 -> 8.1207824 | BD10: ='raw data'!MH11 -> 726.81739 | BE10: ='raw data'!MN11 -> 1.3274085 | BF10: ='raw data'!MT11 -> 314.11944 | BG10: ='raw data'!MZ11 -> 616.46295 | BH10: ='raw data'!NF11 -> 162.68263 | BI10: ='raw data'!NL11 -> 0 | BJ10: ='raw data'!NR11 -> 0.45964848 | BK10: ='raw data'!NX11 -> 3.5751576 | BL10: ='raw data'!OD11 -> 9.6588924 | BM10: ='raw data'!OJ11 -> 0 | BN10: ='raw data'!OP11 -> 1.0051787 | BO10: ='raw data'!OV11 -> 0 | BP10: ='raw data'!PB11 -> 0.037017313 | BQ10: ='raw data'!PH11 -> 1438.363 | BR10: ='raw data'!PN11 -> 1414.0993 | BS10: ='raw data'!PT11 -> 30.498276 | BT10: ='raw data'!PZ11 -> 5168.658 | BU10: ='raw data'!QF11 -> 0.26327005 | BV10: ='raw data'!QL11 -> 59.529008 | BW10: ='raw data'!QR11 -> 0.004159522
A11: ='raw data'!C12 -> CoCiNe-1-2 | B11: ='raw data'!J12 -> 312.12381 | C11: ='raw data'!P12 -> 17.744597 | D11: ='raw data'!V12 -> 191.72448 | E11: ='raw data'!AB12 -> 0.90676876 | F11: ='raw data'!AH12 -> 0.67982535 | G11: ='raw data'!AN12 -> 129323.67 | H11: ='raw data'!AT12 -> 4.0343983 | I11: ='raw data'!AZ12 -> 2855.5811 | J11: ='raw data'!BF12 -> 215.75044 | K11: ='raw data'!BL12 -> 0 | L11: ='raw data'!BR12 -> 0 | M11: ='raw data'!BX12 -> 0 | N11: ='raw data'!CD12 -> 3370.1486 | O11: ='raw data'!CJ12 -> 52.665375 | P11: ='raw data'!CP12 -> 0.46795822 | Q11: ='raw data'!CV12 -> 0.19087829 | R11: ='raw data'!DB12 -> 0 | S11: ='raw data'!DH12 -> 2.1110696 | T11: ='raw data'!DN12 -> 20.477895 | U11: ='raw data'!DT12 -> 3.2274895 | V11: ='raw data'!DZ12 -> 0 | W11: ='raw data'!EF12 -> 0 | X11: ='raw data'!EL12 -> 4.2366599 | Y11: ='raw data'!ER12 -> 12.886021 | Z11: ='raw data'!EX12 -> 942.80977 | AA11: ='raw data'!FD12 -> 68.319186 | AB11: ='raw data'!FJ12 -> 0.75830397 | AC11: ='raw data'!FP12 -> 1.979814 | AD11: ='raw data'!FV12 -> 143.80909 | AE11: ='raw data'!GB12 -> 0 | AF11: ='raw data'!GH12 -> 0 | AG11: ='raw data'!GN12 -> 0 | AH11: ='raw data'!HF12 -> 0 | AI11: ='raw data'!HL12 -> 211966.65 | AJ11: ='raw data'!HR12 -> 2765.1841 | AK11: ='raw data'!HX12 -> 3.4363444 | AL11: ='raw data'!ID12 -> 1878.2321 | AM11: ='raw data'!IJ12 -> 29.504035 | AN11: ='raw data'!IP12 -> 27.47575 | AO11: ='raw data'!IV12 -> 0 | AP11: ='raw data'!JB12 -> 35.669086 | AQ11: ='raw data'!JH12 -> 0.50290949 | AR11: ='raw data'!JN12 -> 15.83567 | AS11: ='raw data'!JT12 -> 1.9441949 | AT11: ='raw data'!JZ12 -> 10.896314 | AU11: ='raw data'!KF12 -> 275.28269 | AV11: ='raw data'!KL12 -> 0 | AW11: ='raw data'!KR12 -> 149.23158 | AX11: ='raw data'!KX12 -> 0 | AY11: ='raw data'!LD12 -> 5643.9504 | AZ11: ='raw data'!LJ12 -> 0 | BA11: ='raw data'!LP12 -> 11.623979 | BB11: ='raw data'!LV12 -> 187.56746 | BC11: ='raw data'!MB12 -> 9.518975 | BD11: ='raw data'!MH12 -> 657.46852 | BE11: ='raw data'!MN12 -> 1.163237 | BF11: ='raw data'!MT12 -> 306.6198 | BG11: ='raw data'!MZ12 -> 622.9808 | BH11: ='raw data'!NF12 -> 132.9691 | BI11: ='raw data'!NL12 -> 0 | BJ11: ='raw data'!NR12 -> 0.4261378 | BK11: ='raw data'!NX12 -> 5.1460744 | BL11: ='raw data'!OD12 -> 9.1146028 | BM11: ='raw data'!OJ12 -> 0 | BN11: ='raw data'!OP12 -> 0.45778241 | BO11: ='raw data'!OV12 -> 14.786608 | BP11: ='raw data'!PB12 -> 0.16587638 | BQ11: ='raw data'!PH12 -> 989.37025 | BR11: ='raw data'!PN12 -> 2250.6628 | BS11: ='raw data'!PT12 -> 23.820344 | BT11: ='raw data'!PZ12 -> 5935.8247 | BU11: ='raw data'!QF12 -> 0.19285454 | BV11: ='raw data'!QL12 -> 70.009907 | BW11: ='raw data'!QR12 -> 0.010117014
A12: ='raw data'!C13 -> CoCiNe-1-3 | B12: ='raw data'!J13 -> 336.90561 | C12: ='raw data'!P13 -> 18.032979 | D12: ='raw data'!V13 -> 211.78182 | E12: ='raw data'!AB13 -> 1.0834237 | F12: ='raw data'!AH13 -> 0.63855418 | G12: ='raw data'!AN13 -> 128300.68 | H12: ='raw data'!AT13 -> 2.8977424 | I12: ='raw data'!AZ13 -> 2665.51 | J12: ='raw data'!BF13 -> 202.80569 | K12: ='raw data'!BL13 -> 0 | L12: ='raw data'!BR13 -> 0 | M12: ='raw data'!BX13 -> 31.282409 | N12: ='raw data'!CD13 -> 2520.4368 | O12: ='raw data'!CJ13 -> 55.843103 | P12: ='raw data'!CP13 -> 0.48601774 | Q12: ='raw data'!CV13 -> 0.1907411 | R12: ='raw data'!DB13 -> 0 | S12: ='raw data'!DH13 -> 2.0865224 | T12: ='raw data'!DN13 -> 21.287702 | U12: ='raw data'!DT13 -> 3.6587437 | V12: ='raw data'!DZ13 -> 0 | W12: ='raw data'!EF13 -> 0 | X12: ='raw data'!EL13 -> 4.5606398 | Y12: ='raw data'!ER13 -> 13.770959 | Z12: ='raw data'!EX13 -> 1048.1326 | AA12: ='raw data'!FD13 -> 69.359313 | AB12: ='raw data'!FJ13 -> 0.70240951 | AC12: ='raw data'!FP13 -> 1.91781 | AD12: ='raw data'!FV13 -> 146.84482 | AE12: ='raw data'!GB13 -> 0 | AF12: ='raw data'!GH13 -> 0 | AG12: ='raw data'!GN13 -> 0 | AH12: ='raw data'!HF13 -> 0 | AI12: ='raw data'!HL13 -> 168151.74 | AJ12: ='raw data'!HR13 -> 8382.3957 | AK12: ='raw data'!HX13 -> 4.7102508 | AL12: ='raw data'!ID13 -> 1810.4764 | AM12: ='raw data'!IJ13 -> 24.92249 | AN12: ='raw data'!IP13 -> 30.124728 | AO12: ='raw data'!IV13 -> 0 | AP12: ='raw data'!JB13 -> 36.897657 | AQ12: ='raw data'!JH13 -> 0.50177814 | AR12: ='raw data'!JN13 -> 16.272599 | AS12: ='raw data'!JT13 -> 1.9820637 | AT12: ='raw data'!JZ13 -> 11.09035 | AU12: ='raw data'!KF13 -> 269.99565 | AV12: ='raw data'!KL13 -> 51613.204 | AW12: ='raw data'!KR13 -> 160.72111 | AX12: ='raw data'!KX13 -> 0 | AY12: ='raw data'!LD13 -> 7329.3326 | AZ12: ='raw data'!LJ13 -> 0 | BA12: ='raw data'!LP13 -> 9.1411812 | BB12: ='raw data'!LV13 -> 123.29105 | BC12: ='raw data'!MB13 -> 7.8040318 | BD12: ='raw data'!MH13 -> 556.66792 | BE12: ='raw data'!MN13 -> 1.4134047 | BF12: ='raw data'!MT13 -> 322.56258 | BG12: ='raw data'!MZ13 -> 608.01773 | BH12: ='raw data'!NF13 -> 134.77698 | BI12: ='raw data'!NL13 -> 0 | BJ12: ='raw data'!NR13 -> 0.36892204 | BK12: ='raw data'!NX13 -> 18.051145 | BL12: ='raw data'!OD13 -> 9.8419133 | BM12: ='raw data'!OJ13 -> 0 | BN12: ='raw data'!OP13 -> 0.41172874 | BO12: ='raw data'!OV13 -> 13.742604 | BP12: ='raw data'!PB13 -> 0.1247408 | BQ12: ='raw data'!PH13 -> 0 | BR12: ='raw data'!PN13 -> 2399.2552 | BS12: ='raw data'!PT13 -> 30.312451 | BT12: ='raw data'!PZ13 -> 4074.1391 | BU12: ='raw data'!QF13 -> 0.16064024 | BV12: ='raw data'!QL13 -> 46.888956 | BW12: ='raw data'!QR13 -> 0.015815432
A13: ='raw data'!C14 -> CoCiNe-2-1 | B13: ='raw data'!J14 -> 201.11752 | C13: ='raw data'!P14 -> 17.585895 | D13: ='raw data'!V14 -> 176.6254 | E13: ='raw data'!AB14 -> 1.0985687 | F13: ='raw data'!AH14 -> 0.29621962 | G13: ='raw data'!AN14 -> 117263.75 | H13: ='raw data'!AT14 -> 4.2003042 | I13: ='raw data'!AZ14 -> 3260.661 | J13: ='raw data'!BF14 -> 200.53745 | K13: ='raw data'!BL14 -> 0 | L13: ='raw data'!BR14 -> 0 | M13: ='raw data'!BX14 -> 0 | N13: ='raw data'!CD14 -> 4037.5642 | O13: ='raw data'!CJ14 -> 48.118823 | P13: ='raw data'!CP14 -> 0.55907118 | Q13: ='raw data'!CV14 -> 0.20542418 | R13: ='raw data'!DB14 -> 0 | S13: ='raw data'!DH14 -> 2.5282777 | T13: ='raw data'!DN14 -> 27.137041 | U13: ='raw data'!DT14 -> 2.5102222 | V13: ='raw data'!DZ14 -> 0 | W13: ='raw data'!EF14 -> 0 | X13: ='raw data'!EL14 -> 3.9008415 | Y13: ='raw data'!ER14 -> 13.347137 | Z13: ='raw data'!EX14 -> 1247.4151 | AA13: ='raw data'!FD14 -> 29.045483 | AB13: ='raw data'!FJ14 -> 0.60786765 | AC13: ='raw data'!FP14 -> 1.3040085 | AD13: ='raw data'!FV14 -> 228.06979 | AE13: ='raw data'!GB14 -> 1.3754784 | AF13: ='raw data'!GH14 -> 0 | AG13: ='raw data'!GN14 -> 0 | AH13: ='raw data'!HF14 -> 0 | AI13: ='raw data'!HL14 -> 421289.91 | AJ13: ='raw data'!HR14 -> 589.51048 | AK13: ='raw data'!HX14 -> 4.8208341 | AL13: ='raw data'!ID14 -> 1568.9088 | AM13: ='raw data'!IJ14 -> 19.677574 | AN13: ='raw data'!IP14 -> 26.023456 | AO13: ='raw data'!IV14 -> 0 | AP13: ='raw data'!JB14 -> 26.282917 | AQ13: ='raw data'!JH14 -> 0.562024 | AR13: ='raw data'!JN14 -> 17.456459 | AS13: ='raw data'!JT14 -> 1.8368129 | AT13: ='raw data'!JZ14 -> 11.700356 | AU13: ='raw data'!KF14 -> 311.15864 | AV13: ='raw data'!KL14 -> 0 | AW13: ='raw data'!KR14 -> 174.21115 | AX13: ='raw data'!KX14 -> 0 | AY13: ='raw data'!LD14 -> 4014.1549 | AZ13: ='raw data'!LJ14 -> 0 | BA13: ='raw data'!LP14 -> 7.5120532 | BB13: ='raw data'!LV14 -> 267.10774 | BC13: ='raw data'!MB14 -> 9.4848015 | BD13: ='raw data'!MH14 -> 656.51143 | BE13: ='raw data'!MN14 -> 1.3927708 | BF13: ='raw data'!MT14 -> 291.19854 | BG13: ='raw data'!MZ14 -> 482.63544 | BH13: ='raw data'!NF14 -> 136.40064 | BI13: ='raw data'!NL14 -> 0 | BJ13: ='raw data'!NR14 -> 0.39200975 | BK13: ='raw data'!NX14 -> 16.506904 | BL13: ='raw data'!OD14 -> 3.8123859 | BM13: ='raw data'!OJ14 -> 0 | BN13: ='raw data'!OP14 -> 0.4256251 | BO13: ='raw data'!OV14 -> 44.614759 | BP13: ='raw data'!PB14 -> 0.094763486 | BQ13: ='raw data'!PH14 -> 0 | BR13: ='raw data'!PN14 -> 2247.5221 | BS13: ='raw data'!PT14 -> 27.528585 | BT13: ='raw data'!PZ14 -> 4157.4216 | BU13: ='raw data'!QF14 -> 0.14701828 | BV13: ='raw data'!QL14 -> 69.579076 | BW13: ='raw data'!QR14 -> 0
... A72: ='raw data'!C73 -> SeqVP41-3-3 | B72: ='raw data'!J73 -> 0 | C72: ='raw data'!P73 -> 24.119691 | D72: ='raw data'!V73 -> 518.95264 | E72: ='raw data'!AB73 -> 0.78695897 | F72: ='raw data'!AH73 -> 0.54701456 | G72: ='raw data'!AN73 -> 70152.123 | H72: ='raw data'!AT73 -> 5.1977774 | I72: ='raw data'!AZ73 -> 4748.3961 | J72: ='raw data'!BF73 -> 398.09956 | K72: ='raw data'!BL73 -> 0 | L72: ='raw data'!BR73 -> 0.001364944 | M72: ='raw data'!BX73 -> 0 | N72: ='raw data'!CD73 -> 3435.68 | O72: ='raw data'!CJ73 -> 38.277676 | P72: ='raw data'!CP73 -> 0.56731919 | Q72: ='raw data'!CV73 -> 0.89353362 | R72: ='raw data'!DB73 -> 0 | S72: ='raw data'!DH73 -> 0.5479478 | T72: ='raw data'!DN73 -> 7.3494298 | U72: ='raw data'!DT73 -> 1.5401222 | V72: ='raw data'!DZ73 -> 0 | W72: ='raw data'!EF73 -> 0.010023861 | X72: ='raw data'!EL73 -> 5.1071016 | Y72: ='raw data'!ER73 -> 12.092255 | Z72: ='raw data'!EX73 -> 1089.9678 | AA72: ='raw data'!FD73 -> 163.75506 | AB72: ='raw data'!FJ73 -> 2.7691534 | AC72: ='raw data'!FP73 -> 1.2778385 | AD72: ='raw data'!FV73 -> 360.33502 | AE72: ='raw data'!GB73 -> 7.0003104 | AF72: ='raw data'!GH73 -> 0 | AG72: ='raw data'!GN73 -> 0 | AH72: ='raw data'!HF73 -> 0 | AI72: ='raw data'!HL73 -> 38444.501 | AJ72: ='raw data'!HR73 -> 541.20297 | AK72: ='raw data'!HX73 -> 4.9460662 | AL72: ='raw data'!ID73 -> 1500.7543 | AM72: ='raw data'!IJ73 -> 22.947139 | AN72: ='raw data'!IP73 -> 19.4927 | AO72: ='raw data'!IV73 -> 0 | AP72: ='raw data'!JB73 -> 42.048392 | AQ72: ='raw data'!JH73 -> 0.37993841 | AR72: ='raw data'!JN73 -> 29.446343 | AS72: ='raw data'!JT73 -> 2.0633793 | AT72: ='raw data'!JZ73 -> 10.882758 | AU72: ='raw data'!KF73 -> 176.24324 | AV72: ='raw data'!KL73 -> 0 | AW72: ='raw data'!KR73 -> 158.86102 | AX72: ='raw data'!KX73 -> 0 | AY72: ='raw data'!LD73 -> 2477.9311 | AZ72: ='raw data'!LJ73 -> 0 | BA72: ='raw data'!LP73 -> 12.544079 | BB72: ='raw data'!LV73 -> 272.479 | BC72: ='raw data'!MB73 -> 8.1213507 | BD72: ='raw data'!MH73 -> 312.19293 | BE72: ='raw data'!MN73 -> 2.1692181 | BF72: ='raw data'!MT73 -> 372.84601 | BG72: ='raw data'!MZ73 -> 134.97376 | BH72: ='raw data'!NF73 -> 85.676882 | BI72: ='raw data'!NL73 -> 0 | BJ72: ='raw data'!NR73 -> 0.44443494 | BK72: ='raw data'!NX73 -> 7.7574729 | BL72: ='raw data'!OD73 -> 6.0051814 | BM72: ='raw data'!OJ73 -> 0 | BN72: ='raw data'!OP73 -> 0.50303823 | BO72: ='raw data'!OV73 -> 0 | BP72: ='raw data'!PB73 -> 0.088693997 | BQ72: ='raw data'!PH73 -> 778.86962 | BR72: ='raw data'!PN73 -> 781.8715 | BS72: ='raw data'!PT73 -> 24.745812 | BT72: ='raw data'!PZ73 -> 3031.0229 | BU72: ='raw data'!QF73 -> 0.4477695 | BV72: ='raw data'!QL73 -> 62.38332 | BW72: ='raw data'!QR73 -> 0

Sheet raw data
A1: Sample | I1: 1-butanol Results | N1: d10-1-butanol (ISTD) Results | O1: 1-heptanol Results | T1: d7-heptyl alcohol​ (ISTD) Results | U1: 1-hexanol Results | Z1: d13-hexyl alcohol​ (ISTD) Results | AA1: 1-nonanol Results | AF1: d7-heptyl alcohol​ (ISTD) Results | AG1: 1-octen-3-ol Results | AL1: d3-1-octen-3-ol​ (ISTD) Results | AM1: 2,3 butane diol Results | AR1: d6-2,3 butane diol (ISTD) Results | AS1: 2-heptanol Results | AX1: d7-heptyl alcohol​ (ISTD) Results | AY1: 2-methyl-1-propanol Results | BD1: d13-hexyl alcohol​ (ISTD) Results | BE1: 2-methyl-butanoic acid Results | BJ1: d13-hexyl alcohol​ (ISTD) Results | BK1: 2-nonanone Results | BP1: d5-2-nonanone​ (ISTD) Results | BQ1: 3,4-dimethylphenol Results | BV1: d10-4-ethylphenol​ (ISTD) Results | BW1: 3-methyl thiopropanol Results | CB1: d13-hexyl alcohol​ (ISTD) Results | CC1: 3-methyl-1-butanol Results | CH1: d5-2-phenyl ethanol​ (ISTD) Results | CI1: 3-methyl-1-pentanol Results | CN1: d11-3-methyl-1-butanol​ (ISTD) Results | CO1: 3-octanol Results | CT1: d3-1-octen-3-ol​ (ISTD) Results | CU1: 4-ethyl guaiacol Results | CZ1: d5-4-ethyl-2-methoxyphenol​ (ISTD) Results | DA1: 4-ethylphenol Results | DF1: d10-4-ethylphenol​ (ISTD) Results | DG1: 4-vinylguaiacol Results | DL1: d5-4-ethyl-2-methoxyphenol​ (ISTD) Results | DM1: 4-vinylphenol Results | DR1: d5-2-phenyl ethanol​ (ISTD) Results | DS1: 5-methylfurfural Results | DX1: d3-furfural​ (ISTD) Results | DY1: acetovanillone Results | ED1: d3-acetovanillone (ISTD) Results | EE1: a-ionone Results | EJ1: d3-β-ionone​ (ISTD) Results | EK1: a-terpineol Results | EP1: d3-α-terpineol​ (ISTD) Results | EQ1: b-cintronellol Results | EV1: d4-diethyl succinate​ (ISTD) Results | EW1: B-damascenone Results | FB1: d4-diethyl succinate​ (ISTD) Results | FC1: benzyl alcohol Results | FH1: d5-2-phenyl ethanol​ (ISTD) Results | FI1: b-ionone Results | FN1: d3-β-ionone​ (ISTD) Results | FO1: butyl acetate Results | FT1: d3-3-methylbutyl acetate​ (ISTD) Results | FU1: butyric acid Results | FZ1: d2-limonene​ (ISTD) Results | GA1: cis-3-hexen-1-ol Results | GF1: d7-heptyl alcohol​ (ISTD) Results | GG1: cis-rose-oxide Results | GL1: d3-linalool​ (ISTD) Results | GM1: cis-whiskey lactone Results | GR1: d5-4-ethyl-2-methoxyphenol​ (ISTD) Results | GS1: d3-vanillin Results | GX1: d3-acetovanillone (ISTD) Results | GY1: d6-ethyl isobutyrate Results | HD1: d10-1-butanol (ISTD) Results | HE1: d6-nerol​ Results | HJ1: d3-β-ionone​ (ISTD) Results | HK1: decanoic acid Results | HP1: d3-furfural​ (ISTD) Results | HQ1: diacetyl Results | HV1: d11-3-methyl-1-butanol​ (ISTD) Results | HW1: diethyl glutarate Results | IB1: d4-diethyl succinate​ (ISTD) Results | IC1: diethyl succinate Results | IH1: d4-diethyl succinate​ (ISTD) Results | II1: Ethyl 2-methyl butyrate Results | IN1: d9-ethyl 2-methylbutyrate​ (ISTD) Results | IO1: Ethyl 3-methyl butyrate Results | IT1: d9-ethyl 3-methylbutyrate​ (ISTD) Results | IU1: Ethyl Acetate Results | IZ1: d3-3-methylbutyl acetate​ (ISTD) Results | JA1: Ethyl Butyrate Results | JF1: d3-ethyl butyrate (ISTD) Results | JG1: ethyl cinnamate Results | JL1: d5-ethyl trans-cinnamate​ (ISTD) Results | JM1: ethyl decanoate Results | JR1: d19-ethyl decanoate​ (ISTD) Results | JS1: ethyl heptanoate Results | JX1: d13-ethyl heptanoate​ (ISTD) Results | JY1: ethyl hexanoate Results | KD1: d11-ethyl hexanoate​ (ISTD) Results | KE1: ethyl isobutyrate Results | KJ1: d3-ethyl butyrate (ISTD) Results | KK1: ethyl L-(-)-lactate Results | KP1: d11-3-methyl-1-butanol​ (ISTD) Results | KQ1: ethyl octanoate Results | KV1: d13-ethyl heptanoate​ (ISTD) Results | KW1: ethyl vanillate Results | LB1: d3-eugenol​ (ISTD) Results | LC1: ethyl-2-hydroxy-4-methylpentanoate Results | LH1: d3-hexyl acetate​ (ISTD) Results | LI1: eugenol Results | LN1: d3-eugenol​ (ISTD) Results | LO1: furfural Results | LT1: d3-furfural​ (ISTD) Results | LU1: furfuryl alcohol Results | LZ1: d5-furfuryl alcohol (ISTD) Results | MA1: gamma-nonalactone Results | MF1: d7-γ-nonalactone​ (ISTD) Results | MG1: Hexanoic Acid Results | ML1: d11-hexnaoic acid​ (ISTD) Results | MM1: hexyl acetate Results | MR1: d3-hexyl acetate​ (ISTD) Results | MS1: isoamyl acetate Results | MX1: d3-3-methylbutyl acetate​ (ISTD) Results | MY1: isoamyl lactate Results | ND1: d11-ethyl hexanoate​ (ISTD) Results | NE1: isobutyl acetate Results | NJ1: d3-3-methylbutyl acetate​ (ISTD) Results | NK1: isoeugenol Results | NP1: d3-eugenol​ (ISTD) Results | NQ1: limonene Results | NV1: d2-limonene​ (ISTD) Results | NW1: Linalool Results | OB1: d3-linalool​ (ISTD) Results | OC1: linalool oxide Results | OH1: d3-linalool​ (ISTD) Results | OI1: methyl nonanoate Results | ON1: d15-methyl octanoate​ (ISTD) Results | OO1: methyl salicyclate Results | OT1: d3-eugenol​ (ISTD) Results | OU1: methyl vanillate Results | OZ1: d3-eugenol​ (ISTD) Results | PA1: nerol Results | PF1: d7-heptyl alcohol​ (ISTD) Results | PG1: nerolidol Results | PL1: d3-linalool​ (ISTD) Results | PM1: octanoic acid Results | PR1: d11-hexnaoic acid​ (ISTD) Results | PS1: phenethyl acetate Results | PX1: d5-benzyl acetate​ (ISTD) Results | PY1: Phenethyl alcohol Results | QD1: d5-2-phenyl ethanol​ (ISTD) Results | QE1: terpinen-4-ol Results | QJ1: d3-α-terpineol​ (ISTD) Results | QK1: trans-2-hexen-1-ol Results | QP1: d2-trans-2-hexen-1-ol​ (ISTD) Results | QQ1: trans-2-octen-1-ol Results | QV1: d3-1-octen-3-ol​ (ISTD) Results | QW1: vanillin Results | RB1: d3-eugenol​ (ISTD) Results
C2: Name | D2: Type | E2: Level | F2: Comment | G2: Dil. | H2: Acq. Date-Time | I2: RT | J2: Final Conc. | K2: Accuracy | L2: Area | M2: Calc. Conc. | N2: Area | O2: RT | P2: Final Conc. | Q2: Accuracy | R2: Area | S2: Calc. Conc. | T2: Area | U2: RT | V2: Final Conc. | W2: Accuracy | X2: Area | Y2: Calc. Conc. | Z2: Area | AA2: RT | AB2: Final Conc. | AC2: Accuracy | AD2: Area | AE2: Calc. Conc. | AF2: Area | AG2: RT | AH2: Final Conc. | AI2: Accuracy | AJ2: Area | AK2: Calc. Conc. | AL2: Area | AM2: RT | AN2: Final Conc. | AO2: Accuracy | AP2: Area | AQ2: Calc. Conc. | AR2: Area | AS2: RT | AT2: Final Conc. | AU2: Accuracy | AV2: Area | AW2: Calc. Conc. | AX2: Area | AY2: RT | AZ2: Final Conc. | BA2: Accuracy | BB2: Area | BC2: Calc. Conc. | BD2: Area | BE2: RT | BF2: Final Conc. | BG2: Accuracy | BH2: Area | BI2: Calc. Conc. | BJ2: Area | BK2: RT | BL2: Final Conc. | BM2: Accuracy | BN2: Area | BO2: Calc. Conc. | BP2: Area | BQ2: RT | BR2: Final Conc. | BS2: Accuracy | BT2: Area | BU2: Calc. Conc. | BV2: Area | BW2: RT | BX2: Final Conc. | BY2: Accuracy | BZ2: Area | CA2: Calc. Conc. | CB2: Area | CC2: RT | CD2: Final Conc. | CE2: Accuracy | CF2: Area | CG2: Calc. Conc. | CH2: Area | CI2: RT | CJ2: Final Conc. | CK2: Accuracy | CL2: Area | CM2: Calc. Conc. | CN2: Area | CO2: RT | CP2: Final Conc. | CQ2: Accuracy | CR2: Area | CS2: Calc. Conc. | CT2: Area | CU2: RT | CV2: Final Conc. | CW2: Accuracy | CX2: Area | CY2: Calc. Conc. | CZ2: Area | DA2: RT | DB2: Final Conc. | DC2: Accuracy | DD2: Area | DE2: Calc. Conc. | DF2: Area | DG2: RT | DH2: Final Conc. | DI2: Accuracy | DJ2: Area | DK2: Calc. Conc. | DL2: Area | DM2: RT | DN2: Final Conc. | DO2: Accuracy | DP2: Area | DQ2: Calc. Conc. | DR2: Area | DS2: RT | DT2: Final Conc. | DU2: Accuracy | DV2: Area | DW2: Calc. Conc. | DX2: Area | DY2: RT | DZ2: Final Conc. | EA2: Accuracy | EB2: Area | EC2: Calc. Conc. | ED2: Area | EE2: RT | EF2: Final Conc. | EG2: Accuracy | EH2: Area | EI2: Calc. Conc. | EJ2: Area | EK2: RT | EL2: Final Conc. | EM2: Accuracy | EN2: Area | EO2: Calc. Conc. | EP2: Area | EQ2: RT | ER2: Final Conc. | ES2: Accuracy | ET2: Area | EU2: Calc. Conc. | EV2: Area | EW2: RT | EX2: Final Conc. | EY2: Accuracy | EZ2: Area | FA2: Calc. Conc. | FB2: Area | FC2: RT | FD2: Final Conc. | FE2: Accuracy | FF2: Area | FG2: Calc. Conc. | FH2: Area | FI2: RT | FJ2: Final Conc. | FK2: Accuracy | FL2: Area | FM2: Calc. Conc. | FN2: Area | FO2: RT | FP2: Final Conc. | FQ2: Accuracy | FR2: Area | FS2: Calc. Conc. | FT2: Area | FU2: RT | FV2: Final Conc. | FW2: Accuracy | FX2: Area | FY2: Calc. Conc. | FZ2: Area | GA2: RT | GB2: Final Conc. | GC2: Accuracy | GD2: Area | GE2: Calc. Conc. | GF2: Area | GG2: RT | GH2: Final Conc. | GI2: Accuracy | GJ2: Area | GK2: Calc. Conc. | GL2: Area | GM2: RT | GN2: Final Conc. | GO2: Accuracy | GP2: Area | GQ2: Calc. Conc. | GR2: Area | GS2: RT | GT2: Final Conc. | GU2: Accuracy | GV2: Area | GW2: Calc. Conc. | GX2: Area | GY2: RT | GZ2: Final Conc. | HA2: Accuracy | HB2: Area | HC2: Calc. Conc. | HD2: Area | HE2: RT | HF2: Final Conc. | HG2: Accuracy | HH2: Area | HI2: Calc. Conc. | HJ2: Area | HK2: RT | HL2: Final Conc. | HM2: Accuracy | HN2: Area | HO2: Calc. Conc. | HP2: Area | HQ2: RT | HR2: Final Conc. | HS2: Accuracy | HT2: Area | HU2: Calc. Conc. | HV2: Area | HW2: RT | HX2: Final Conc. | HY2: Accuracy | HZ2: Area | IA2: Calc. Conc. | IB2: Area | IC2: RT | ID2: Final Conc. | IE2: Accuracy | IF2: Area | IG2: Calc. Conc. | IH2: Area | II2: RT | IJ2: Final Conc. | IK2: Accuracy | IL2: Area | IM2: Calc. Conc. | IN2: Area | IO2: RT | IP2: Final Conc. | IQ2: Accuracy | IR2: Area | IS2: Calc. Conc. | IT2: Area | IU2: RT | IV2: Final Conc. | IW2: Accuracy | IX2: Area | IY2: Calc. Conc. | IZ2: Area | JA2: RT | JB2: Final Conc. | JC2: Accuracy | JD2: Area | JE2: Calc. Conc. | JF2: Area | JG2: RT | JH2: Final Conc. | JI2: Accuracy | JJ2: Area | JK2: Calc. Conc. | JL2: Area | JM2: RT | JN2: Final Conc. | JO2: Accuracy | JP2: Area | JQ2: Calc. Conc. | JR2: Area | JS2: RT | JT2: Final Conc. | JU2: Accuracy | JV2: Area | JW2: Calc. Conc. | JX2: Area | JY2: RT | JZ2: Final Conc. | KA2: Accuracy | KB2: Area | KC2: Calc. Conc. | KD2: Area | KE2: RT | KF2: Final Conc. | KG2: Accuracy | KH2: Area | KI2: Calc. Conc. | KJ2: Area | KK2: RT | KL2: Final Conc. | KM2: Accuracy | KN2: Area | KO2: Calc. Conc. | KP2: Area | KQ2: RT | KR2: Final Conc. | KS2: Accuracy | KT2: Area | KU2: Calc. Conc. | KV2: Area | KW2: RT | KX2: Final Conc. | KY2: Accuracy | KZ2: Area | LA2: Calc. Conc. | LB2: Area | LC2: RT | LD2: Final Conc. | LE2: Accuracy | LF2: Area | LG2: Calc. Conc. | LH2: Area | LI2: RT | LJ2: Final Conc. | LK2: Accuracy | LL2: Area | LM2: Calc. Conc. | LN2: Area | LO2: RT | LP2: Final Conc. | LQ2: Accuracy | LR2: Area | LS2: Calc. Conc. | LT2: Area | LU2: RT | LV2: Final Conc. | LW2: Accuracy | LX2: Area | LY2: Calc. Conc. | LZ2: Area | MA2: RT | MB2: Final Conc. | MC2: Accuracy | MD2: Area | ME2: Calc. Conc. | MF2: Area | MG2: RT | MH2: Final Conc. | MI2: Accuracy | MJ2: Area | MK2: Calc. Conc. | ML2: Area | MM2: RT | MN2: Final Conc. | MO2: Accuracy | MP2: Area | MQ2: Calc. Conc. | MR2: Area | MS2: RT | MT2: Final Conc. | MU2: Accuracy | MV2: Area | MW2: Calc. Conc. | MX2: Area | MY2: RT | MZ2: Final Conc. | NA2: Accuracy | NB2: Area | NC2: Calc. Conc. | ND2: Area | NE2: RT | NF2: Final Conc. | NG2: Accuracy | NH2: Area | NI2: Calc. Conc. | NJ2: Area | NK2: RT | NL2: Final Conc. | NM2: Accuracy | NN2: Area | NO2: Calc. Conc. | NP2: Area | NQ2: RT | NR2: Final Conc. | NS2: Accuracy | NT2: Area | NU2: Calc. Conc. | NV2: Area | NW2: RT | NX2: Final Conc. | NY2: Accuracy | NZ2: Area | OA2: Calc. Conc. | OB2: Area | OC2: RT | OD2: Final Conc. | OE2: Accuracy | OF2: Area | OG2: Calc. Conc. | OH2: Area | OI2: RT | OJ2: Final Conc. | OK2: Accuracy | OL2: Area | OM2: Calc. Conc. | ON2: Area | OO2: RT | OP2: Final Conc. | OQ2: Accuracy | OR2: Area | OS2: Calc. Conc. | OT2: Area | OU2: RT | OV2: Final Conc. | OW2: Accuracy | OX2: Area | OY2: Calc. Conc. | OZ2: Area | PA2: RT | PB2: Final Conc. | PC2: Accuracy | PD2: Area | PE2: Calc. Conc. | PF2: Area | PG2: RT | PH2: Final Conc. | PI2: Accuracy | PJ2: Area | PK2: Calc. Conc. | PL2: Area | PM2: RT | PN2: Final Conc. | PO2: Accuracy | PP2: Area | PQ2: Calc. Conc. | PR2: Area | PS2: RT | PT2: Final Conc. | PU2: Accuracy | PV2: Area | PW2: Calc. Conc. | PX2: Area | PY2: RT | PZ2: Final Conc. | QA2: Accuracy | QB2: Area | QC2: Calc. Conc. | QD2: Area | QE2: RT | QF2: Final Conc. | QG2: Accuracy | QH2: Area | QI2: Calc. Conc. | QJ2: Area | QK2: RT | QL2: Final Conc. | QM2: Accuracy | QN2: Area | QO2: Calc. Conc. | QP2: Area | QQ2: RT | QR2: Final Conc. | QS2: Accuracy | QT2: Area | QU2: Calc. Conc. | QV2: Area | QW2: RT | QX2: Final Conc. | QY2: Accuracy | QZ2: Area | RA2: Calc. Conc. | RB2: Area
C3: CoBerry-1-1 | D3: Sample | G3: 1 | H3: 46094.673 | I3: 19.770033 | J3: 80.330783 | L3: 3.3448378e+08 | M3: 80.330783 | N3: 4394066.1 | O3: 40.4404 | P3: 16.498006 | R3: 29976.468 | S3: 16.498006 | T3: 718110.82 | U3: 34.341567 | V3: 0 | X3: 98086457 | Y3: 0 | Z3: 35602779 | AA3: 52.459967 | AB3: 1.0663582 | AD3: 165898.34 | AE3: 1.0663582 | AF3: 718110.82 | AG3: 39.50825 | AH3: 0.1995125 | AJ3: 4153.1788 | AK3: 0.1995125 | AL3: 18815.143 | AM3: 47.989267 | AN3: 81158.332 | AP3: 163194.6 | AQ3: 81158.332 | AR3: 18946.661 | AS3: 32.16385 | AT3: 4.8530104 | AV3: 135239.04 | AW3: 4.8530104 | AX3: 718110.82 | AY3: 35.021833 | AZ3: 2750.7619 | BB3: 214594.26 | BC3: 2750.7619 | BD3: 35602779 | BE3: 53.218633 | BF3: 120.65137 | BH3: 7007996.6 | BI3: 120.65137 | BJ3: 35602779 | BK3: 35.262983 | BL3: 0 | BN3: 71925.564 | BO3: 0 | BP3: 2694230 | BQ3: 78.659983 | BR3: 0 | BT3: 14530.783 | BU3: 0 | BV3: 1883241.3 | BW3: 55.784683 | BX3: 0 | BZ3: 732748.63 | CA3: 0 | CB3: 35602779 | CC3: 24.732217 | CD3: 4295.9958 | CF3: 14792067 | CG3: 4295.9958 | CH3: 62545941 | CI3: 32.734417 | CJ3: 55.911331 | CL3: 1526397.2 | CM3: 55.911331 | CN3: 64022265 | CO3: 36.47005 | CP3: 0.57731571 | CR3: 28219.043 | CS3: 0.57731571 | CT3: 18815.143 | CU3: 71.784383 | CV3: 0.80288396 | CX3: 35041.101 | CY3: 0.80288396 | CZ3: 1057835.9 | DA3: 78.660533 | DB3: 0 | DD3: 16217.457 | DE3: 0 | DF3: 1883241.3 | DG3: 79.509783 | DH3: 1.1191337 | DJ3: 16132.236 | DK3: 1.1191337 | DL3: 1057835.9 | DM3: 88.088083 | DN3: 11.852753 | DP3: 14895.85 | DQ3: 11.852753 | DR3: 62545941 | DS3: 47.086333 | DT3: 1.8807312 | DV3: 49959.766 | DW3: 1.8807312 | DX3: 1039426.2 | DY3: 100.0002 | DZ3: 2.847898 | EB3: 9128.5378 | EC3: 2.847898 | ED3: 23319.502 | EE3: 62.5398 | EF3: 0 | EH3: 17190.38 | EI3: 0 | EJ3: 209557.77 | EK3: 54.5044 | EL3: 3.3452245 | EN3: 32512.734 | EO3: 3.3452245 | EP3: 37849.22 | EQ3: 58.36585 | ER3: 13.901689 | ET3: 8402.3852 | EU3: 13.901689 | EV3: 39758342 | EW3: 60.926367 | EX3: 1124.1194 | EZ3: 479154.28 | FA3: 1124.1194 | FB3: 39758342 | FC3: 64.230833 | FD3: 265.28418 | FF3: 6308205.2 | FG3: 265.28418 | FH3: 62545941 | FI3: 67.0892 | FJ3: 0.92670216 | FL3: 27801.863 | FM3: 0.92670216 | FN3: 209557.77 | FO3: 17.14355 | FP3: 0.79494369 | FR3: 35029.095 | FS3: 0.79494369 | FT3: 7257990.6 | FU3: 50.64385 | FV3: 188.61833 | FX3: 14547284 | FY3: 188.61833 | FZ3: 74177.141 | GA3: 34.339983 | GB3: 0 | GD3: 40673384 | GE3: 0 | GF3: 718110.82 | GG3: 33.741133 | GH3: 0 | GJ3: 4968.2698 | GK3: 0 | GL3: 12719.249 | GM3: 68.08675 | GN3: 0 | GP3: 1032.9057 | GQ3: 0 | GR3: 1057835.9 | GS3: 95.612183 | GV3: 2647.9972 | GX3: 23319.502 | HD3: 4394066.1 | HE3: 60.621933 | HH3: 2984.5068 | HJ3: 209557.77 | HK3: 82.229183 | HL3: 230923.11 | HN3: 867152.6 | HO3: 230923.11 | HP3: 1039426.2 | HQ3: 14.305433 | HR3: 0 | HT3: 49612.996 | HU3: 0 | HV3: 64022265 | HW3: 58.9467 | HX3: 4.1076672 | HZ3: 107472.6 | IA3: 4.1076672 | IB3: 39758342 | IC3: 53.216283 | ID3: 1619.491 | IF3: 72954609 | IG3: 1619.491 | IH3: 39758342 | II3: 15.213383 | IJ3: 18.307917 | IL3: 2086251.4 | IM3: 18.307917 | IN3: 671667.94 | IO3: 15.98545 | IP3: 22.42976 | IR3: 2211666 | IS3: 22.42976 | IT3: 774687 | IU3: 7.7544833 | IV3: 5563.1076 | IX3: 2.6883377e+08 | IY3: 5563.1076 | IZ3: 7257990.6 | JA3: 14.327583 | JB3: 55.401453 | JD3: 2299691.5 | JE3: 55.401453 | JF3: 774175.91 | JG3: 76.51735 | JH3: 0.4231299 | JJ3: 30703.596 | JK3: 0.4231299 | JL3: 2869542.2 | JM3: 50.641633 | JN3: 14.037872 | JP3: 47649251 | JQ3: 14.037872 | JR3: 1.8796757e+08 | JS3: 31.340267 | JT3: 1.4273572 | JV3: 401136.23 | JW3: 1.4273572 | JX3: 23397341 | JY3: 24.72925 | JZ3: 10.207492 | KB3: 34270380 | KC3: 10.207492 | KD3: 7987953.7 | KE3: 10.798483 | KF3: 400.3772 | KH3: 878352.44 | KI3: 400.3772 | KJ3: 774175.91 | KK3: 33.97095 | KL3: 21435.572 | KN3: 63722445 | KO3: 21435.572 | KP3: 64022265 | KQ3: 37.987017 | KR3: 145.37834 | KT3: 75615829 | KU3: 145.37834 | KV3: 23397341 | KW3: 99.969483 | KX3: 0 | KZ3: 2047.743 | LA3: 0 | LB3: 16134.181 | LC3: 45.55725 | LD3: 5441.1641 | LF3: 10568387 | LG3: 5441.1641 | LH3: 402075.59 | LI3: 78.168517 | LJ3: 0 | LL3: 6588.4773 | LM3: 0 | LN3: 16134.181 | LO3: 40.501017 | LP3: 11.619044 | LR3: 929868.55 | LS3: 11.619044 | LT3: 1039426.2 | LU3: 52.45375 | LV3: 262.57484 | LX3: 23993.137 | LY3: 262.57484 | LZ3: 51271.15 | MA3: 71.634683 | MB3: 6.2670151 | MD3: 90289.206 | ME3: 6.2670151 | MF3: 1080715.3 | MG3: 63.186733 | MH3: 366.16221 | MJ3: 5065726.7 | MK3: 366.16221 | ML3: 891710.42 | MM3: 27.3625 | MN3: 1.3162683 | MP3: 63934.049 | MQ3: 1.3162683 | MR3: 402075.59 | MS3: 18.71815 | MT3: 344.77386 | MV3: 42923733 | MW3: 344.77386 | MX3: 7257990.6 | MY3: 47.136733 | MZ3: 560.56389 | NB3: 4429314.4 | NC3: 560.56389 | ND3: 7987953.7 | NE3: 13.17885 | NF3: 0 | NH3: 260664.2 | NI3: 0 | NJ3: 7257990.6 | NK3: 86.3263 | NL3: 0 | NN3: 444.54053 | NO3: 0 | NP3: 16134.181 | NQ3: 21.863283 | NR3: 0.19432485 | NT3: 192942.58 | NU3: 0.19432485 | NV3: 74177.141 | NW3: 45.762417 | NX3: 7.4266935 | NZ3: 19467.114 | OA3: 7.4266935 | OB3: 12719.249 | OC3: 41.288967 | OD3: 8.609931 | OF3: 29568.739 | OG3: 8.609931 | OH3: 12719.249 | OI3: 41.589167 | OJ3: 0 | OL3: 213.36527 | OM3: 0 | ON3: 81289398 | OO3: 58.3478 | OP3: 0.62681568 | OR3: 396428.06 | OS3: 0.62681568 | OT3: 16134.181 | OU3: 98.001683 | OV3: 3.2974894 | OX3: 10290.383 | OY3: 3.2974894 | OZ3: 16134.181 | PA3: 58.34045 | PB3: 0.42058653 | PD3: 49605.441 | PE3: 0.42058653 | PF3: 718110.82 | PG3: 71.3259 | PH3: 210.07853 | PJ3: 61245.94 | PK3: 210.07853 | PL3: 12719.249 | PM3: 74.062967 | PN3: 1145.3635 | PP3: 140397.8 | PQ3: 1145.3635 | PR3: 891710.42 | PS3: 60.680683 | PT3: 24.40157 | PV3: 5209961.1 | PW3: 24.40157 | PX3: 17067812 | PY3: 66.07855 | PZ3: 3927.064 | QB3: 4.1252937e+08 | QC3: 3927.064 | QD3: 62545941 | QE3: 48.943017 | QF3: 0.22662696 | QH3: 7076.9356 | QI3: 0.22662696 | QJ3: 37849.22 | QK3: 37.9845 | QL3: 40.699293 | QN3: 2952385.1 | QO3: 40.699293 | QP3: 23100.907 | QQ3: 47.080167 | QR3: 0 | QT3: 6725.2333 | QU3: 0 | QV3: 18815.143 | QW3: 95.762367 | QX3: 0 | QZ3: 23043.031 | RA3: 0 | RB3: 16134.181
